Workbook
Name BoxPlot: "BoxPlot"
Name Bubble: "Bubble"
Name Candlestick: "Candlestick"
Name Chart: "Chart"
Name ChartImage: "ChartImage"
Name ColumnRange: "ColumnRange"
Name Dumbbell: "Dumbbell"
Name Heatmap: "Heatmap"
Name Histogram: "Histogram"
Name Map: "Map"
Name OHLC: "OHLC"
Name PieChart: "PieChart"
Name Scatter: "Scatter"
Name Series: "Series"
Name Stripe: "Stripe"
Name Table: "Table"
Name TreeMap: "TreeMap"
Name Waterfall: "Waterfall"

Sheet Activities before completion
A4: Type | B4: A Office
A5: Status | B5: Valid | D5: <- Not included completed projects
A6: Ownership Structure | B6: (All)
A7: Floor Plate > 15,000 sf (NFA) | B7: (All)
B9: Column Labels
B10: Total Sum of Pre-leased space (Usable FA) (sf) | C10: Total Sum of Pre-sold (Usable FA) (sf) | D10: Total Sum of Self-use space (Usable FA) (sf) | O10: KLN & NT | P10: KLN & NT | Q10: KLN & NT | R10: KLN & NT
A11: Row Labels | O11: Sum of Pre-leased space (Usable FA) (sf) | P11: Sum of Pre-sold (Usable FA) (sf) | Q11: Sum of Self-use space (Usable FA) (sf) | R11: Total
A12: Grand Total | O12: =E12+H12 -> 0 | P12: =F12+I12 -> 0 | Q12: =G12+J12 -> 0 | R12: =SUM(O12:Q12) -> 0
O13: =E13+H13 -> 0 | P13: =F13+I13 -> 0 | Q13: =G13+J13 -> 0 | R13: =SUM(O13:Q13) -> 0
O14: =E14+H14 -> 0 | P14: =F14+I14 -> 0 | Q14: =G14+J14 -> 0 | R14: =SUM(O14:Q14) -> 0
O15: =E15+H15 -> 0 | P15: =F15+I15 -> 0 | Q15: =G15+J15 -> 0 | R15: =SUM(O15:Q15) -> 0
N16: =SUM(K16:M16) -> 0
A26: Type | B26: A Office
A27: Status | B27: Valid | D27: <- Not included completed projects
A28: Ownership Structure | B28: (All)
A29: Floor Plate > 15,000 sf (NFA) | B29: (All)
B31: Column Labels
B32: Total Sum of Space available for lease (Usable FA) (sf) | C32: Total Sum of Space available for sale (Usable FA) (sf) | D32: Total Sum of Space available uncertain of use (Usable FA) (sf) | O32: KLN & NT | P32: KLN & NT | Q32: KLN & NT | R32: KLN & NT
A33: Row Labels | O33: Sum of Space available for lease (Usable FA) (sf) | P33: Sum of Space available for sale (Usable FA) (sf) | Q33: Sum of Space available uncertain of use (Usable FA) (sf) | R33: Total
A34: Grand Total | O34: =E34+H34 -> 0 | P34: =F34+I34 -> 0 | Q34: =G34+J34 -> 0 | R34: =SUM(O34:Q34) -> 0
O35: =E35+H35 -> 0 | P35: =F35+I35 -> 0 | Q35: =G35+J35 -> 0 | R35: =SUM(O35:Q35) -> 0
O36: =E36+H36 -> 0 | P36: =F36+I36 -> 0 | Q36: =G36+J36 -> 0 | R36: =SUM(O36:Q36) -> 0
O37: =E37+H37 -> 0 | P37: =F37+I37 -> 0 | Q37: =G37+J37 -> 0 | R37: =SUM(O37:Q37) -> 0
O38: =E38+H38 -> 0 | P38: =F38+I38 -> 0 | Q38: =G38+J38 -> 0 | R38: =SUM(O38:Q38) -> 0
O39: =E39+H39 -> 0 | P39: =F39+I39 -> 0 | Q39: =G39+J39 -> 0 | R39: =SUM(O39:Q39) -> 0

Sheet NEW table
A1: Type | B1: A Office
A2: Status | B2: (Multiple Items) | Q2: Type | R2: A Office
A3: Ownership Structure | B3: (All) | Q3: Status | R3: (Multiple Items)
A4: Floor Plate > 15,000 sf (NFA) | B4: (All) | Q4: Ownership Structure | R4: (All)
A5: Private / Public Sector | B5: (All) | Q5: Floor Plate > 15,000 sf (NFA) | R5: (All)
A7: Sum of Office UFA (Net) (sf) | B7: Column Labels | Q7: Sum of Office UFA (Net) (sf) | S7: CBRE districts
B8: Central | C8: Admiralty & Sheung Wan | D8: Wan Chai & Causeway Bay | E8: Hong Kong East | F8: Wong Chuk Hang | G8: Tsim Sha Tsui West | H8: Kowloon East | I8: Kowloon Others | J8: New Territories | K8: Grand Total | Q8: Year | R8: Qtr | S8: Central | T8: Admiralty & Sheung Wan | U8: Wan Chai & Causeway Bay | V8: Hong Kong East | W8: Wong Chuk Hang | X8: Tsim Sha Tsui | Y8: Kowloon East | Z8: Kowloon Others | AA8: New Territories | AB8: Tsim Sha Tsui West | AC8: Grand Total
A9: Row Labels | Q9: 2008 | R9: 1 | V9: 1214462.6 | AB9: 714454.26 | AC9: 1928916.8
A10: 2022 | B10: 0 | C10: 0 | D10: 0 | E10: 718002 | F10: 291512.85 | G10: 0 | H10: 1880197.9 | I10: 0 | J10: 1246999 | K10: 4136711.7 | R10: 2 | AA10: 431108.96 | AC10: 431108.96
A11: 2023 | B11: 0 | C11: 0 | D11: 0 | E11: 0 | F11: 0 | G11: 0 | H11: 346226.65 | I11: 1265376.8 | J11: 0 | K11: 1611603.4 | R11: 3 | Y11: 2028181.6 | AC11: 2028181.6
A12: 2024 | B12: 752009.51 | C12: 0 | D12: 351511.45 | E12: 0 | F12: 241267.41 | G12: 0 | H12: 211444.8 | I12: 0 | J12: 0 | K12: 1556233.2 | R12: 4
A13: 2025 | B13: 78036.8 | C13: 122128.8 | D13: 466387.68 | E13: 0 | F13: 0 | G13: 1921374 | H13: 328053.53 | I13: 0 | J13: 0 | K13: 2915980.8 | Q13: 2009 | R13: 1 | Z13: 165456.67 | AB13: 607129.38 | AC13: 772586.05
A14: 2026 | B14: 324000 | C14: 477416.54 | D14: 752964 | E14: 0 | F14: 0 | G14: 0 | H14: 178329.6 | I14: 0 | J14: 0 | K14: 1732710.1 | R14: 2
A15: 2027 | B15: 0 | C15: 135224.72 | D15: 0 | E15: 105000 | F15: 0 | G15: 504033.07 | H15: 0 | I15: 379486.41 | J15: 431964 | K15: 1555708.2 | R15: 3 | Y15: 565418.65 | AC15: 565418.65
A16: 2028 | B16: 0 | C16: 0 | D16: 0 | E16: 0 | F16: 0 | G16: 0 | H16: 0 | I16: 242856.91 | J16: 0 | K16: 242856.91 | R16: 4 | Y16: 233710.12 | AC16: 233710.12
A17: 2029 | B17: 0 | C17: 0 | D17: 0 | E17: 0 | F17: 0 | G17: 0 | H17: 0 | I17: 880056.79 | J17: 0 | K17: 880056.79 | Q17: 2010 | R17: 1 | Y17: 291505.5 | AC17: 291505.5
A18: 2030 | B18: 0 | C18: 0 | D18: 0 | E18: 701149.5 | F18: 0 | G18: 0 | H18: 0 | I18: 0 | J18: 266957.96 | K18: 968107.46 | R18: 2 | AB18: 465089.04 | AC18: 465089.04
A19: 2032 | B19: 297000 | C19: 0 | D19: 0 | E19: 0 | F19: 0 | G19: 0 | H19: 0 | I19: 0 | J19: 0 | K19: 297000 | R19: 3 | V19: 375913.75 | AC19: 375913.75
A20: 2033 | B20: 0 | C20: 0 | D20: 0 | E20: 0 | F20: 0 | G20: 0 | H20: 531682.84 | I20: 0 | J20: 0 | K20: 531682.84 | R20: 4
A21: Grand Total | B21: 1451046.3 | C21: 734770.06 | D21: 1570863.1 | E21: 1524151.5 | F21: 532780.26 | G21: 2425407.1 | H21: 3475935.3 | I21: 2767776.9 | J21: 1945921 | K21: 16428651 | Q21: 2011 | R21: 1 | S21: 122648.27 | W21: 491537.15 | Y21: 314640 | AC21: 928825.42
R22: 2 | Y22: 447279 | AC22: 447279
R23: 3
R24: 4 | S24: 215391.02 | AC24: 215391.02
Q25: 2012 | R25: 1 | U25: 222653.53 | Y25: 227618.25 | AC25: 450271.78
R26: 2
R27: 3 | U27: 105603 | Y27: 191442.75 | AC27: 297045.75
R28: 4 | S28: 151474.24 | AA28: 442530.75 | AC28: 594004.99
Q29: 2013 | R29: 1
R30: 2 | W30: 137894.4 | AC30: 137894.4
A31: Type | B31: A Office | R31: 3 | Y31: 714699.41 | AC31: 714699.41
A32: Status | B32: (Multiple Items) | R32: 4 | S32: 50000 | W32: 193064.25 | AC32: 243064.25
A33: Ownership Structure | B33: (All) | Q33: 2014 | R33: 1 | S33: 51630 | Z33: 160988.54 | AC33: 212618.54
A34: Floor Plate > 15,000 sf (NFA) | B34: (All) | R34: 2
R35: 3 | AA35: 293429.24 | AC35: 293429.24
A36: Sum of Office UFA (Net) (sf) | B36: Column Labels | R36: 4 | Y36: 132741 | AC36: 132741
A37: Row Labels | B37: Hong Kong Island | C37: Kowloon | D37: New Territories | E37: Grand Total | G37: KLN/NT | Q37: 2015 | R37: 1 | Y37: 395916.05 | Z37: 115286 | AC37: 511202.05
A38: 2022 | B38: 1009514.8 | C38: 1880197.9 | D38: 1246999 | E38: 4136711.7 | G38: =+C38+D38 -> 3127196.9 | R38: 2 | W38: 82390 | X38: 60889.5 | Y38: 694424.39 | AC38: 837703.89
A39: 2023 | C39: 1611603.4 | E39: 1611603.4 | F39: 1422396.2 | G39: =+C39+D39 -> 1611603.4 | R39: 3 | U39: 128331.7 | AC39: 128331.7
A40: 2024 | B40: 1344788.4 | C40: 211444.8 | E40: 1556233.2 | F40: 381637.69 | G40: =+C40+D40 -> 211444.8 | R40: 4 | W40: 351215.8 | AA40: 170281 | AC40: 521496.8
A41: 2025 | B41: 666553.28 | C41: 2249427.5 | E41: 2915980.8 | F41: 886141.4 | G41: =+C41+D41 -> 2249427.5 | Q41: 2016 | R41: 1 | S41: 61882.8 | Z41: 446760 | AC41: 508642.8
...

Sheet Grade A Office Supply_pre-2020
A1: Chinese Name | B1: Building Name | C1: Street Name | D1: Lot No. | E1: CBRE sub-markets | F1: CBRE districts | G1: District Order | H1: Area | I1: Year | J1: Qtr | K1: CBRE EDC | L1: Type | M1: Status | N1: No. of Blocks | O1: No. of Storeys | P1: No. of Storeys for Office | Q1: Floor Plate (GFA) (sf) | R1: Floor Plate (NFA) (sf) | S1: Floor Plate > 15,000 sf (NFA) | T1: Total GFA (sm) | U1: Total GFA (sf) | V1: Office GFA (sm) | W1: Office GFA (sf) | X1: Office UFA (Net) (sm) | Y1: Office UFA (Net) (sf) | Z1: Pre-leased space (Usable FA) (sf) | AA1: Pre-sold (Usable FA) (sf) | AB1: Self-use space (Usable FA) (sf) | AC1: Space available for lease (Usable FA) (sf) | AD1: Space available for sale (Usable FA) (sf) | AE1: Space available uncertain of use (Usable FA) (sf) | AF1: Pre-commitment Rate (%) | AG1: Building Type | AH1: BD Status | AI1: Source of Information | AJ1: Date of Source | AK1: Date of Entry | AL1: Development | AM1: Developer | AN1: Private / Public Sector | AO1: For Sale or For Lease? | AP1: Ownership Structure | AQ1: Remarks | AR1: Item Code | AS1: ProjectID | AT1: Lat | AU1: Long | AV1: Geometry
A2: 港島東中心 | B2: One Island East | C2: 18 Westlands Road | E2: Quarry Bay | F2: =VLOOKUP(Table1[[#This Row],[CBRE sub-markets]],Reference!$A$2:$B$31,2,FALSE) -> Hong Kong East | G2: =VLOOKUP(Table1[[#This Row],[CBRE sub-markets]],Reference!$A$2:$D$31,3,FALSE) -> 4 | H2: =VLOOKUP(Table1[[#This Row],[CBRE sub-markets]],Reference!$A$2:$D$31,4,FALSE) -> Hong Kong Island | I2: 2008 | J2: 1 | K2: =IF(ISNUMBER(Table1[[#This Row],[Qtr]]),CONCATENATE(Table1[[#This Row],[Year]]," Q",Table1[[#This Row],[Qtr]]),CONCATENATE(Table1[[#This Row],[Year]],Table1[[#This Row],[Qtr]])) -> 2008 Q1 | L2: A Office | M2: Completed | N2: 1 | O2: 68+2 basement | Q2: 25000 | R2: =Q2*(Y2/W2) -> 23000 | S2: =IF(AND(ISNUMBER(R2),R2>=15000),"Yes",IF(R2="","Unknown","No")) -> Yes | V2: 142791.8 | W2: 1320068 | X2: 103258.9 | Y2: 1214462.6 | AC2: =IF(Table1[[#This Row],[For Sale or For Lease?]]="For Lease",Table1[[#This Row],[Office UFA (Net) (sf)]]-Table1[[#This Row],[Pre-leased space (Usable FA) (sf)]]-Table1[[#This Row],[Pre-sold (Usable FA) (sf)]]-Table1[[#This Row],[Self-use space (Usable FA) (sf)]],0) -> 1214462.6 | AD2: =IF(Table1[[#This Row],[For Sale or For Lease?]]="For Sale",Table1[[#This Row],[Office UFA (Net) (sf)]]-Table1[[#This Row],[Pre-leased space (Usable FA) (sf)]]-Table1[[#This Row],[Pre-sold (Usable FA) (sf)]]-Table1[[#This Row],[Self-use space (Usable FA) (sf)]],0) -> 0 | AE2: =IF(Table1[[#This Row],[For Sale or For Lease?]]="Uncertain",Table1[[#This Row],[Office UFA (Net) (sf)]]-Table1[[#This Row],[Pre-leased space (Usable FA) (sf)]]-Table1[[#This Row],[Pre-sold (Usable FA) (sf)]]-Table1[[#This Row],[Self-use space (Usable FA) (sf)]],0) -> 0 | AF2: =1-SUM(Table1[[#This Row],[Space available for lease (Usable FA) (sf)]:[Space available uncertain of use (Usable FA) (sf)]])/Table1[[#This Row],[Office UFA (Net) (sf)]] -> 0 | AG2: Commercial | AH2: OP Issued | AI2: BD Monthly Digest | AJ2: 39508 | AK2: 40043 | AM2: Swire Properties | AN2: Private Sector | AO2: For Lease | AP2: Single owner | AQ2: Completed. Phase 1: 1,000,000 sf to be completed in 2008; Phase 2: 1,500,000 sf to be completed in 2010 | AR2: HE011
A3: 環球貿易廣場1期 | B3: International Commerce Centre Phase 1 | C3: 1 Austin Road West (Union Square Phase 7) | E3: Tsim Sha Tsui West | F3: =VLOOKUP(Table1[[#This Row],[CBRE sub-markets]],Reference!$A$2:$B$31,2,FALSE) -> Tsim Sha Tsui West | G3: =VLOOKUP(Table1[[#This Row],[CBRE sub-markets]],Reference!$A$2:$D$31,3,FALSE) -> 6 | H3: =VLOOKUP(Table1[[#This Row],[CBRE sub-markets]],Reference!$A$2:$D$31,4,FALSE) -> Kowloon | I3: 2008 | J3: 1 | K3: =IF(ISNUMBER(Table1[[#This Row],[Qtr]]),CONCATENATE(Table1[[#This Row],[Year]]," Q",Table1[[#This Row],[Qtr]]),CONCATENATE(Table1[[#This Row],[Year]],Table1[[#This Row],[Qtr]])) -> 2008 Q1 | L3: A Office | M3: Completed | N3: 1 | O3: 108+4 basement (10-47/F Total 32 floors) | Q3: 38000 | R3: =Q3*(Y3/W3) -> 29640 | S3: =IF(AND(ISNUMBER(R3),R3>=15000),"Yes",IF(R3="","Unknown","No")) -> Yes | V3: =W3/10.764 -> 85095.411 | W3: 915967 | X3: =Y3/10.764 -> 66374.42 | Y3: 714454.26 | AC3: =IF(Table1[[#This Row],[For Sale or For Lease?]]="For Lease",Table1[[#This Row],[Office UFA (Net) (sf)]]-Table1[[#This Row],[Pre-leased space (Usable FA) (sf)]]-Table1[[#This Row],[Pre-sold (Usable FA) (sf)]]-Table1[[#This Row],[Self-use space (Usable FA) (sf)]],0) -> 714454.26 | AD3: =IF(Table1[[#This Row],[For Sale or For Lease?]]="For Sale",Table1[[#This Row],[Office UFA (Net) (sf)]]-Table1[[#This Row],[Pre-leased space (Usable FA) (sf)]]-Table1[[#This Row],[Pre-sold (Usable FA) (sf)]]-Table1[[#This Row],[Self-use space (Usable FA) (sf)]],0) -> 0 | AE3: =IF(Table1[[#This Row],[For Sale or For Lease?]]="Uncertain",Table1[[#This Row],[Office UFA (Net) (sf)]]-Table1[[#This Row],[Pre-leased space (Usable FA) (sf)]]-Table1[[#This Row],[Pre-sold (Usable FA) (sf)]]-Table1[[#This Row],[Self-use space (Usable FA) (sf)]],0) -> 0 | AF3: =1-SUM(Table1[[#This Row],[Space available for lease (Usable FA) (sf)]:[Space available uncertain of use (Usable FA) (sf)]])/Table1[[#This Row],[Office UFA (Net) (sf)]] -> 0 | AG3: Commercial/ Hotel | AH3: POP Issued | AI3: Old Database | AK3: 40043 | AL3: Site | AM3: Sun Hung Kai Properties | AN3: Private Sector | AO3: For Lease | AP3: Single owner | AR3: TS031
A4: 九龍貿易中心 1座 | B4: Kowloon Commerce Centre Tower A | C4: 51-53 Kwai Cheong Road & 12-120 Tai Lin Pai Road | E4: Kwai Chung & Tsuen Wan | F4: =VLOOKUP(Table1[[#This Row],[CBRE sub-markets]],Reference!$A$2:$B$31,2,FALSE) -> New Territories | G4: =VLOOKUP(Table1[[#This Row],[CBRE sub-markets]],Reference!$A$2:$D$31,3,FALSE) -> 9 | H4: =VLOOKUP(Table1[[#This Row],[CBRE sub-markets]],Reference!$A$2:$D$31,4,FALSE) -> New Territories | I4: 2008 | J4: 2 | K4: =IF(ISNUMBER(Table1[[#This Row],[Qtr]]),CONCATENATE(Table1[[#This Row],[Year]]," Q",Table1[[#This Row],[Qtr]]),CONCATENATE(Table1[[#This Row],[Year]],Table1[[#This Row],[Qtr]])) -> 2008 Q2 | L4: A Office | M4: Completed | N4: 1 | O4: 26+7 podium+1 basement | Q4: =W4/(26+7) -> 17501.285 | R4: =Q4*(Y4/W4) -> 13063.908 | S4: =IF(AND(ISNUMBER(R4),R4>=15000),"Yes",IF(R4="","Unknown","No")) -> No | V4: 53655 | W4: =V4*10.764 -> 577542.42 | X4: 40051 | Y4: =X4*10.764 -> 431108.96 | AC4: =IF(Table1[[#This Row],[For Sale or For Lease?]]="For Lease",Table1[[#This Row],[Office UFA (Net) (sf)]]-Table1[[#This Row],[Pre-leased space (Usable FA) (sf)]]-Table1[[#This Row],[Pre-sold (Usable FA) (sf)]]-Table1[[#This Row],[Self-use space (Usable FA) (sf)]],0) -> 431108.96 | AD4: =IF(Table1[[#This Row],[For Sale or For Lease?]]="For Sale",Table1[[#This Row],[Office UFA (Net) (sf)]]-Table1[[#This Row],[Pre-leased space (Usable FA) (sf)]]-Table1[[#This Row],[Pre-sold (Usable FA) (sf)]]-Table1[[#This Row],[Self-use space (Usable FA) (sf)]],0) -> 0 | AE4: =IF(Table1[[#This Row],[For Sale or For Lease?]]="Uncertain",Table1[[#This Row],[Office UFA (Net) (sf)]]-Table1[[#This Row],[Pre-leased space (Usable FA) (sf)]]-Table1[[#This Row],[Pre-sold (Usable FA) (sf)]]-Table1[[#This Row],[Self-use space (Usable FA) (sf)]],0) -> 0 | AF4: =1-SUM(Table1[[#This Row],[Space available for lease (Usable FA) (sf)]:[Space available uncertain of use (Usable FA) (sf)]])/Table1[[#This Row],[Office UFA (Net) (sf)]] -> 0 | AG4: Commercial | AH4: OP Issued | AI4: BD Monthly Digest | AJ4: 39600 | AK4: 40043 | AM4: Sun Hung Kai Properties | AN4: Private Sector | AO4: For Lease | AP4: Single owner | AQ4: Almost fully leased | AR4: KF006
A5: 國際交易中心 | B5: Exchange Tower | C5: 33 Wang Chiu Road | E5: Kowloon Bay | F5: =VLOOKUP(Table1[[#This Row],[CBRE sub-markets]],Reference!$A$2:$B$31,2,FALSE) -> Kowloon East | G5: =VLOOKUP(Table1[[#This Row],[CBRE sub-markets]],Reference!$A$2:$D$31,3,FALSE) -> 7 | H5: =VLOOKUP(Table1[[#This Row],[CBRE sub-markets]],Reference!$A$2:$D$31,4,FALSE) -> Kowloon | I5: 2008 | J5: 3 | K5: =IF(ISNUMBER(Table1[[#This Row],[Qtr]]),CONCATENATE(Table1[[#This Row],[Year]]," Q",Table1[[#This Row],[Qtr]]),CONCATENATE(Table1[[#This Row],[Year]],Table1[[#This Row],[Qtr]])) -> 2008 Q3 | L5: A Office | M5: Completed | N5: 1 | O5: 28+3 basement | Q5: =W5/28 -> 21750.93 | R5: =Q5*(Y5/W5) -> 18503.316 | S5: =IF(AND(ISNUMBER(R5),R5>=15000),"Yes",IF(R5="","Unknown","No")) -> Yes | V5: 56579.9 | W5: =V5*10.764 -> 609026.04 | X5: 48132 | Y5: =X5*10.764 -> 518092.85 | AC5: =IF(Table1[[#This Row],[For Sale or For Lease?]]="For Lease",Table1[[#This Row],[Office UFA (Net) (sf)]]-Table1[[#This Row],[Pre-leased space (Usable FA) (sf)]]-Table1[[#This Row],[Pre-sold (Usable FA) (sf)]]-Table1[[#This Row],[Self-use space (Usable FA) (sf)]],0) -> 518092.85 | AD5: =IF(Table1[[#This Row],[For Sale or For Lease?]]="For Sale",Table1[[#This Row],[Office UFA (Net) (sf)]]-Table1[[#This Row],[Pre-leased space (Usable FA) (sf)]]-Table1[[#This Row],[Pre-sold (Usable FA) (sf)]]-Table1[[#This Row],[Self-use space (Usable FA) (sf)]],0) -> 0 | AE5: =IF(Table1[[#This Row],[For Sale or For Lease?]]="Uncertain",Table1[[#This Row],[Office UFA (Net) (sf)]]-Table1[[#This Row],[Pre-leased space (Usable FA) (sf)]]-Table1[[#This Row],[Pre-sold (Usable FA) (sf)]]-Table1[[#This Row],[Self-use space (Usable FA) (sf)]],0) -> 0 | AF5: =1-SUM(Table1[[#This Row],[Space available for lease (Usable FA) (sf)]:[Space available uncertain of use (Usable FA) (sf)]])/Table1[[#This Row],[Office UFA (Net) (sf)]] -> 0 | AG5: Commercial | AH5: OP Issued | AI5: BD Monthly Digest | AJ5: 39692 | AK5: 40043 | AM5: Sino Land | AN5: Private Sector | AO5: For Lease | AP5: Single owner | AQ5: Land premium = $1,282 psf, 16 Mar 07. Sam Li (7 Jun 2011): almost fully leased | AR5: KK019
B6: Manhattan Place | C6: 1 Sheung Yee Road (7 Wang Mau Street & 23 Wang Tai Road) | E6: Kowloon Bay | F6: =VLOOKUP(Table1[[#This Row],[CBRE sub-markets]],Reference!$A$2:$B$31,2,FALSE) -> Kowloon East | G6: =VLOOKUP(Table1[[#This Row],[CBRE sub-markets]],Reference!$A$2:$D$31,3,FALSE) -> 7 | H6: =VLOOKUP(Table1[[#This Row],[CBRE sub-markets]],Reference!$A$2:$D$31,4,FALSE) -> Kowloon | I6: 2008 | J6: 3 | K6: =IF(ISNUMBER(Table1[[#This Row],[Qtr]]),CONCATENATE(Table1[[#This Row],[Year]]," Q",Table1[[#This Row],[Qtr]]),CONCATENATE(Table1[[#This Row],[Year]],Table1[[#This Row],[Qtr]])) -> 2008 Q3 | L6: A Office | M6: Completed | N6: 1 | O6: 41 | Q6: =W6/O6 -> 17256.74 | R6: =Q6*(Y6/W6) -> 13805.268 | S6: =IF(AND(ISNUMBER(R6),R6>=15000),"Yes",IF(R6="","Unknown","No")) -> No | V6: 65730.8 | W6: =V6*10.764 -> 707526.33 | X6: 51142.5 | Y6: 566016 | AC6: =IF(Table1[[#This Row],[For Sale or For Lease?]]="For Lease",Table1[[#This Row],[Office UFA (Net) (sf)]]-Table1[[#This Row],[Pre-leased space (Usable FA) (sf)]]-Table1[[#This Row],[Pre-sold (Usable FA) (sf)]]-Table1[[#This Row],[Self-use space (Usable FA) (sf)]],0) -> 566016 | AD6: =IF(Table1[[#This Row],[For Sale or For Lease?]]="For Sale",Table1[[#This Row],[Office UFA (Net) (sf)]]-Table1[[#This Row],[Pre-leased space (Usable FA) (sf)]]-Table1[[#This Row],[Pre-sold (Usable FA) (sf)]]-Table1[[#This Row],[Self-use space (Usable FA) (sf)]],0) -> 0 | AE6: =IF(Table1[[#This Row],[For Sale or For Lease?]]="Uncertain",Table1[[#This Row],[Office UFA (Net) (sf)]]-Table1[[#This Row],[Pre-leased space (Usable FA) (sf)]]-Table1[[#This Row],[Pre-sold (Usable FA) (sf)]]-Table1[[#This Row],[Self-use space (Usable FA) (sf)]],0) -> 0 | AF6: =1-SUM(Table1[[#This Row],[Space available for lease (Usable FA) (sf)]:[Space available uncertain of use (Usable FA) (sf)]])/Table1[[#This Row],[Office UFA (Net) (sf)]] -> 0 | AG6: Commercial | AH6: OP Issued | AI6: BD Monthly Digest | AJ6: 39661 | AK6: 40043 | AM6: Manhattan Realty | AN6: Private Sector | AO6: For Lease | AP6: Single owner | AQ6: 2 Feb 05 SCMP, EJ 11 Mar 05 Sam Li (7 Jun 2011):Fully leased | AR6: KK018
A7: 城東誌 | B7: One & Two Landmark East | C7: 100 & 102 How Ming Street | E7: Kwun Tong | F7: =VLOOKUP(Table1[[#This Row],[CBRE sub-markets]],Reference!$A$2:$B$31,2,FALSE) -> Kowloon East | G7: =VLOOKUP(Table1[[#This Row],[CBRE sub-markets]],Reference!$A$2:$D$31,3,FALSE) -> 7 | H7: =VLOOKUP(Table1[[#This Row],[CBRE sub-markets]],Reference!$A$2:$D$31,4,FALSE) -> Kowloon | I7: 2008 | J7: 3 | K7: =IF(ISNUMBER(Table1[[#This Row],[Qtr]]),CONCATENATE(Table1[[#This Row],[Year]]," Q",Table1[[#This Row],[Qtr]]),CONCATENATE(Table1[[#This Row],[Year]],Table1[[#This Row],[Qtr]])) -> 2008 Q3 | L7: A Office | M7: Completed | N7: 2 | O7: 2/40/43+2 basement | Q7: =W7/42/2 -> 14315.633 | R7: =Q7*(Y7/W7) -> 11238.961 | S7: =IF(AND(ISNUMBER(R7),R7>=15000),"Yes",IF(R7="","Unknown","No")) -> No | V7: 111716.2 | W7: =V7*10.764 -> 1202513.2 | X7: 87706.5 | Y7: =X7*10.764 -> 944072.77 | AC7: =IF(Table1[[#This Row],[For Sale or For Lease?]]="For Lease",Table1[[#This Row],[Office UFA (Net) (sf)]]-Table1[[#This Row],[Pre-leased space (Usable FA) (sf)]]-Table1[[#This Row],[Pre-sold (Usable FA) (sf)]]-Table1[[#This Row],[Self-use space (Usable FA) (sf)]],0) -> 944072.77 | AD7: =IF(Table1[[#This Row],[For Sale or For Lease?]]="For Sale",Table1[[#This Row],[Office UFA (Net) (sf)]]-Table1[[#This Row],[Pre-leased space (Usable FA) (sf)]]-Table1[[#This Row],[Pre-sold (Usable FA) (sf)]]-Table1[[#This Row],[Self-use space (Usable FA) (sf)]],0) -> 0 | AE7: =IF(Table1[[#This Row],[For Sale or For Lease?]]="Uncertain",Table1[[#This Row],[Office UFA (Net) (sf)]]-Table1[[#This Row],[Pre-leased space (Usable FA) (sf)]]-Table1[[#This Row],[Pre-sold (Usable FA) (sf)]]-Table1[[#This Row],[Self-use space (Usable FA) (sf)]],0) -> 0 | AF7: =1-SUM(Table1[[#This Row],[Space available for lease (Usable FA) (sf)]:[Space available uncertain of use (Usable FA) (sf)]])/Table1[[#This Row],[Office UFA (Net) (sf)]] -> 0 | AG7: Commercial | AH7: OP Issued | AI7: BD Monthly Digest | AJ7: 39692 | AK7: 40043 | AM7: Winsor Properties | AN7: Private Sector | AO7: For Lease | AP7: Single owner | AR7: KK007
A8: 友邦九龍金融中心 | B8: AIA Financial Centre | C8: 712 Prince Edward Road East | E8: San Po Kong | F8: =VLOOKUP(Table1[[#This Row],[CBRE sub-markets]],Reference!$A$2:$B$31,2,FALSE) -> Kowloon Others | G8: =VLOOKUP(Table1[[#This Row],[CBRE sub-markets]],Reference!$A$2:$D$31,3,FALSE) -> 8 | H8: =VLOOKUP(Table1[[#This Row],[CBRE sub-markets]],Reference!$A$2:$D$31,4,FALSE) -> Kowloon | I8: 2009 | J8: 1 | K8: =IF(ISNUMBER(Table1[[#This Row],[Qtr]]),CONCATENATE(Table1[[#This Row],[Year]]," Q",Table1[[#This Row],[Qtr]]),CONCATENATE(Table1[[#This Row],[Year]],Table1[[#This Row],[Qtr]])) -> 2009 Q1 | L8: A Office | M8: Completed | N8: 1 | O8: 27 | Q8: =+W8/O8 -> 8021.9707 | R8: =Q8*(Y8/W8) -> 6128.0249 | S8: =IF(AND(ISNUMBER(R8),R8>=15000),"Yes",IF(R8="","Unknown","No")) -> No | V8: 20122 | W8: =V8*10.764 -> 216593.21 | X8: 15371.3 | Y8: =X8*10.764 -> 165456.67 | AC8: =IF(Table1[[#This Row],[For Sale or For Lease?]]="For Lease",Table1[[#This Row],[Office UFA (Net) (sf)]]-Table1[[#This Row],[Pre-leased space (Usable FA) (sf)]]-Table1[[#This Row],[Pre-sold (Usable FA) (sf)]]-Table1[[#This Row],[Self-use space (Usable FA) (sf)]],0) -> 165456.67 | AD8: =IF(Table1[[#This Row],[For Sale or For Lease?]]="For Sale",Table1[[#This Row],[Office UFA (Net) (sf)]]-Table1[[#This Row],[Pre-leased space (Usable FA) (sf)]]-Table1[[#This Row],[Pre-sold (Usable FA) (sf)]]-Table1[[#This Row],[Self-use space (Usable FA) (sf)]],0) -> 0 | AE8: =IF(Table1[[#This Row],[For Sale or For Lease?]]="Uncertain",Table1[[#This Row],[Office UFA (Net) (sf)]]-Table1[[#This Row],[Pre-leased space (Usable FA) (sf)]]-Table1[[#This Row],[Pre-sold (Usable FA) (sf)]]-Table1[[#This Row],[Self-use space (Usable FA) (sf)]],0) -> 0 | AF8: =1-SUM(Table1[[#This Row],[Space available for lease (Usable FA) (sf)]:[Space available uncertain of use (Usable FA) (sf)]])/Table1[[#This Row],[Office UFA (Net) (sf)]] -> 0 | AG8: Commercial | AH8: OP Issued | AI8: BD Monthly Digest | AJ8: 39814 | AK8: 40043 | AM8: Henderson | AN8: Private Sector | AO8: For Lease | AP8: Single owner | AR8: SP001
A9: 環球貿易廣場2期 | B9: International Commerce Centre Phase 2 | C9: 1 Austin Road West (Union Square Phase 7) | E9: Tsim Sha Tsui West | F9: =VLOOKUP(Table1[[#This Row],[CBRE sub-markets]],Reference!$A$2:$B$31,2,FALSE) -> Tsim Sha Tsui West | G9: =VLOOKUP(Table1[[#This Row],[CBRE sub-markets]],Reference!$A$2:$D$31,3,FALSE) -> 6 | H9: =VLOOKUP(Table1[[#This Row],[CBRE sub-markets]],Reference!$A$2:$D$31,4,FALSE) -> Kowloon | I9: 2009 | J9: 1 | K9: =IF(ISNUMBER(Table1[[#This Row],[Qtr]]),CONCATENATE(Table1[[#This Row],[Year]]," Q",Table1[[#This Row],[Qtr]]),CONCATENATE(Table1[[#This Row],[Year]],Table1[[#This Row],[Qtr]])) -> 2009 Q1 | L9: A Office | M9: Completed | N9: 1 | O9: 108+4 basement (50-77/F Total 22 floors) | Q9: 35000 | R9: =Q9*(Y9/W9) -> 27300 | S9: =IF(AND(ISNUMBER(R9),R9>=15000),"Yes",IF(R9="","Unknown","No")) -> Yes | V9: =W9/10.764 -> 72312.43 | W9: 778371 | X9: =Y9/10.764 -> 56403.696 | Y9: =W9*0.78 -> 607129.38 | AC9: =IF(Table1[[#This Row],[For Sale or For Lease?]]="For Lease",Table1[[#This Row],[Office UFA (Net) (sf)]]-Table1[[#This Row],[Pre-leased space (Usable FA) (sf)]]-Table1[[#This Row],[Pre-sold (Usable FA) (sf)]]-Table1[[#This Row],[Self-use space (Usable FA) (sf)]],0) -> 607129.38 | AD9: =IF(Table1[[#This Row],[For Sale or For Lease?]]="For Sale",Table1[[#This Row],[Office UFA (Net) (sf)]]-Table1[[#This Row],[Pre-leased space (Usable FA) (sf)]]-Table1[[#This Row],[Pre-sold (Usable FA) (sf)]]-Table1[[#This Row],[Self-use space (Usable FA) (sf)]],0) -> 0 | AE9: =IF(Table1[[#This Row],[For Sale or For Lease?]]="Uncertain",Table1[[#This Row],[Office UFA (Net) (sf)]]-Table1[[#This Row],[Pre-leased space (Usable FA) (sf)]]-Table1[[#This Row],[Pre-sold (Usable FA) (sf)]]-Table1[[#This Row],[Self-use space (Usable FA) (sf)]],0) -> 0 | AF9: =1-SUM(Table1[[#This Row],[Space available for lease (Usable FA) (sf)]:[Space available uncertain of use (Usable FA) (sf)]])/Table1[[#This Row],[Office UFA (Net) (sf)]] -> 0 | AG9: Commercial/ Hotel | AH9: POP Issued | AI9: Old Database | AK9: 40043 | AL9: Site | AM9: Sun Hung Kai Properties | AN9: Private Sector | AO9: For Lease | AP9: Single owner | AQ9: OS-KLN Sam Li (May 2009): POP quoted by L/L | AR9: TS031
A10: 億京中心 | B10: Billion Centre | C10: 1 Wang Kwong Road | E10: Kowloon Bay | F10: =VLOOKUP(Table1[[#This Row],[CBRE sub-markets]],Reference!$A$2:$B$31,2,FALSE) -> Kowloon East | G10: =VLOOKUP(Table1[[#This Row],[CBRE sub-markets]],Reference!$A$2:$D$31,3,FALSE) -> 7 | H10: =VLOOKUP(Table1[[#This Row],[CBRE sub-markets]],Reference!$A$2:$D$31,4,FALSE) -> Kowloon | I10: 2009 | J10: 3 | K10: =IF(ISNUMBER(Table1[[#This Row],[Qtr]]),CONCATENATE(Table1[[#This Row],[Year]]," Q",Table1[[#This Row],[Qtr]]),CONCATENATE(Table1[[#This Row],[Year]],Table1[[#This Row],[Qtr]])) -> 2009 Q3 | L10: A Office | M10: Completed | N10: 1 | O10: 31 | Q10: 27000 | R10: =Q10*(Y10/W10) -> 23151.88 | S10: =IF(AND(ISNUMBER(R10),R10>=15000),"Yes",IF(R10="","Unknown","No")) -> Yes | V10: 50101.4 | W10: =V10*10.764 -> 539291.47 | X10: 42960.8 | Y10: =+X10*10.764 -> 462430.05 | AC10: =IF(Table1[[#This Row],[For Sale or For Lease?]]="For Lease",Table1[[#This Row],[Office UFA (Net) (sf)]]-Table1[[#This Row],[Pre-leased space (Usable FA) (sf)]]-Table1[[#This Row],[Pre-sold (Usable FA) (sf)]]-Table1[[#This Row],[Self-use space (Usable FA) (sf)]],0) -> 0 | AD10: =IF(Table1[[#This Row],[For Sale or For Lease?]]="For Sale",Table1[[#This Row],[Office UFA (Net) (sf)]]-Table1[[#This Row],[Pre-leased space (Usable FA) (sf)]]-Table1[[#This Row],[Pre-sold (Usable FA) (sf)]]-Table1[[#This Row],[Self-use space (Usable FA) (sf)]],0) -> 462430.05 | AE10: =IF(Table1[[#This Row],[For Sale or For Lease?]]="Uncertain",Table1[[#This Row],[Office UFA (Net) (sf)]]-Table1[[#This Row],[Pre-leased space (Usable FA) (sf)]]-Table1[[#This Row],[Pre-sold (Usable FA) (sf)]]-Table1[[#This Row],[Self-use space (Usable FA) (sf)]],0) -> 0 | AF10: =1-SUM(Table1[[#This Row],[Space available for lease (Usable FA) (sf)]:[Space available uncertain of use (Usable FA) (sf)]])/Table1[[#This Row],[Office UFA (Net) (sf)]] -> 0 | AG10: Commercial | AH10: OP Issued | AI10: BD Monthly Digest | AJ10: 40026 | AK10: 40092 | AL10: Redevelopment | AM10: Billion Development | AN10: Private Sector | AO10: For Sale | AP10: Strata-title | AQ10: originally was 星島大廈, bought in 2005 at HK$ 37Mn/ Apple Daily 6Oct09: has sold 70% but will keep 7 floors for leasing/Sam Li (7 Jun 2011):all Billion owned portion has been sold | AR10: KK022
A11: 鱷魚恤中心 | B11: Crocodile Centre | C11: 79 Hoi Yuen Road | E11: Kwun Tong | F11: =VLOOKUP(Table1[[#This Row],[CBRE sub-markets]],Reference!$A$2:$B$31,2,FALSE) -> Kowloon East | G11: =VLOOKUP(Table1[[#This Row],[CBRE sub-markets]],Reference!$A$2:$D$31,3,FALSE) -> 7 | H11: =VLOOKUP(Table1[[#This Row],[CBRE sub-markets]],Reference!$A$2:$D$31,4,FALSE) -> Kowloon | I11: 2009 | J11: 3 | K11: =IF(ISNUMBER(Table1[[#This Row],[Qtr]]),CONCATENATE(Table1[[#This Row],[Year]]," Q",Table1[[#This Row],[Qtr]]),CONCATENATE(Table1[[#This Row],[Year]],Table1[[#This Row],[Qtr]])) -> 2009 Q3 | L11: A Office | M11: Completed | N11: 1 | O11: 23+2 basement | Q11: 11080 | R11: =Q11*(Y11/W11) -> 7922.2 | S11: =IF(AND(ISNUMBER(R11),R11>=15000),"Yes",IF(R11="","Unknown","No")) -> No | V11: =W11/10.764 -> 13381.643 | W11: =11080*(25-10-2) -> 144040 | X11: =V11*0.715 -> 9567.8744 | Y11: =X11*10.764 -> 102988.6 | AC11: =IF(Table1[[#This Row],[For Sale or For Lease?]]="For Lease",Table1[[#This Row],[Office UFA (Net) (sf)]]-Table1[[#This Row],[Pre-leased space (Usable FA) (sf)]]-Table1[[#This Row],[Pre-sold (Usable FA) (sf)]]-Table1[[#This Row],[Self-use space (Usable FA) (sf)]],0) -> 102988.6 | AD11: =IF(Table1[[#This Row],[For Sale or For Lease?]]="For Sale",Table1[[#This Row],[Office UFA (Net) (sf)]]-Table1[[#This Row],[Pre-leased space (Usable FA) (sf)]]-Table1[[#This Row],[Pre-sold (Usable FA) (sf)]]-Table1[[#This Row],[Self-use space (Usable FA) (sf)]],0) -> 0 | AE11: =IF(Table1[[#This Row],[For Sale or For Lease?]]="Uncertain",Table1[[#This Row],[Office UFA (Net) (sf)]]-Table1[[#This Row],[Pre-leased space (Usable FA) (sf)]]-Table1[[#This Row],[Pre-sold (Usable FA) (sf)]]-Table1[[#This Row],[Self-use space (Usable FA) (sf)]],0) -> 0 | AF11: =1-SUM(Table1[[#This Row],[Space available for lease (Usable FA) (sf)]:[Space available uncertain of use (Usable FA) (sf)]])/Table1[[#This Row],[Office UFA (Net) (sf)]] -> 0 | AG11: Commercial | AH11: OP Issued | AI11: BD Monthly Digest | AJ11: 40057 | AK11: 40122 | AM11: Lai Sun Development / Crocodile KT Investment Ltd | AN11: Private Sector | AO11: For Lease | AP11: Single owner | AQ11: Total GFA: 240,000 sf for the entire building including the lower retail portion/ Feb 2009./Sam Li (7 Jun 2011):Fully leased | AR11: KK023
A12: 絲寶國際中心 | B12: C-Bons International Centre (formerly: One Harbour East) | C12: 108 Wai Yip Street | E12: Kwun Tong | F12: =VLOOKUP(Table1[[#This Row],[CBRE sub-markets]],Reference!$A$2:$B$31,2,FALSE) -> Kowloon East | G12: =VLOOKUP(Table1[[#This Row],[CBRE sub-markets]],Reference!$A$2:$D$31,3,FALSE) -> 7 | H12: =VLOOKUP(Table1[[#This Row],[CBRE sub-markets]],Reference!$A$2:$D$31,4,FALSE) -> Kowloon | I12: 2009 | J12: 4 | K12: =IF(ISNUMBER(Table1[[#This Row],[Qtr]]),CONCATENATE(Table1[[#This Row],[Year]]," Q",Table1[[#This Row],[Qtr]]),CONCATENATE(Table1[[#This Row],[Year]],Table1[[#This Row],[Qtr]])) -> 2009 Q4 | L12: A Office | M12: Completed | N12: 1 | O12: 25+1 basement | Q12: =W12/25 -> 11697.196 | R12: =Q12*(Y12/W12) -> 9348.4048 | S12: =IF(AND(ISNUMBER(R12),R12>=15000),"Yes",IF(R12="","Unknown","No")) -> No | V12: 27167.4 | W12: =+V12*10.764 -> 292429.89 | X12: 21712.2 | Y12: =+X12*10.764 -> 233710.12 | AC12: =IF(Table1[[#This Row],[For Sale or For Lease?]]="For Lease",Table1[[#This Row],[Office UFA (Net) (sf)]]-Table1[[#This Row],[Pre-leased space (Usable FA) (sf)]]-Table1[[#This Row],[Pre-sold (Usable FA) (sf)]]-Table1[[#This Row],[Self-use space (Usable FA) (sf)]],0) -> 233710.12 | AD12: =IF(Table1[[#This Row],[For Sale or For Lease?]]="For Sale",Table1[[#This Row],[Office UFA (Net) (sf)]]-Table1[[#This Row],[Pre-leased space (Usable FA) (sf)]]-Table1[[#This Row],[Pre-sold (Usable FA) (sf)]]-Table1[[#This Row],[Self-use space (Usable FA) (sf)]],0) -> 0 | AE12: =IF(Table1[[#This Row],[For Sale or For Lease?]]="Uncertain",Table1[[#This Row],[Office UFA (Net) (sf)]]-Table1[[#This Row],[Pre-leased space (Usable FA) (sf)]]-Table1[[#This Row],[Pre-sold (Usable FA) (sf)]]-Table1[[#This Row],[Self-use space (Usable FA) (sf)]],0) -> 0 | AF12: =1-SUM(Table1[[#This Row],[Space available for lease (Usable FA) (sf)]:[Space available uncertain of use (Usable FA) (sf)]])/Table1[[#This Row],[Office UFA (Net) (sf)]] -> 0 | AG12: Commercial | AH12: OP Issued | AI12: BD Monthly Digest | AJ12: 40148 | AK12: 40212 | AL12: Redevelopment | AM12: Sun Hung Kai Properties | AN12: Private Sector | AO12: For Lease | AP12: Strata-title | AQ12: Previously named as MC7/ [21Aug09 OS-Kln: 1) asking price HK$ 5,000 psf on average 2) asking price of carparking space is approx. HK$ 500,000 3) efficiency is 80% as quoted by the landlord 4) tentative OP at Q1 2010 5) presale consent was granted by the Government ] | AR12: KK024
B13: The Cameron | C13: 33 Cameron Road | E13: Tsim Sha Tsui | F13: =VLOOKUP(Table1[[#This Row],[CBRE sub-markets]],Reference!$A$2:$B$31,2,FALSE) -> Tsim Sha Tsui | G13: =VLOOKUP(Table1[[#This Row],[CBRE sub-markets]],Reference!$A$2:$D$31,3,FALSE) -> 6 | H13: =VLOOKUP(Table1[[#This Row],[CBRE sub-markets]],Reference!$A$2:$D$31,4,FALSE) -> Kowloon | I13: 2009 | J13: 4 | K13: =IF(ISNUMBER(Table1[[#This Row],[Qtr]]),CONCATENATE(Table1[[#This Row],[Year]]," Q",Table1[[#This Row],[Qtr]]),CONCATENATE(Table1[[#This Row],[Year]],Table1[[#This Row],[Qtr]])) -> 2009 Q4 | L13: B Office | M13: Completed | N13: 1 | O13: 25 | Q13: 4000 | R13: =Q13*(Y13/W13) -> 2297.3704 | S13: =IF(AND(ISNUMBER(R13),R13>=15000),"Yes",IF(R13="","Unknown","No")) -> No | V13: 8427.2 | W13: 90710.381 | X13: 4840.1 | Y13: 52098.836 | AC13: =IF(Table1[[#This Row],[For Sale or For Lease?]]="For Lease",Table1[[#This Row],[Office UFA (Net) (sf)]]-Table1[[#This Row],[Pre-leased space (Usable FA) (sf)]]-Table1[[#This Row],[Pre-sold (Usable FA) (sf)]]-Table1[[#This Row],[Self-use space (Usable FA) (sf)]],0) -> 52098.836 | AD13: =IF(Table1[[#This Row],[For Sale or For Lease?]]="For Sale",Table1[[#This Row],[Office UFA (Net) (sf)]]-Table1[[#This Row],[Pre-leased space (Usable FA) (sf)]]-Table1[[#This Row],[Pre-sold (Usable FA) (sf)]]-Table1[[#This Row],[Self-use space (Usable FA) (sf)]],0) -> 0 | AE13: =IF(Table1[[#This Row],[For Sale or For Lease?]]="Uncertain",Table1[[#This Row],[Office UFA (Net) (sf)]]-Table1[[#This Row],[Pre-leased space (Usable FA) (sf)]]-Table1[[#This Row],[Pre-sold (Usable FA) (sf)]]-Table1[[#This Row],[Self-use space (Usable FA) (sf)]],0) -> 0 | AF13: =1-SUM(Table1[[#This Row],[Space available for lease (Usable FA) (sf)]:[Space available uncertain of use (Usable FA) (sf)]])/Table1[[#This Row],[Office UFA (Net) (sf)]] -> 0 | AG13: Commercial | AH13: OP Issued | AI13: BD Monthly Digest | AJ13: 40087 | AK13: 40147 | AM13: Lammington Investment Holdings Ltd | AN13: Private Sector | AO13: For Lease | AP13: Single owner | AQ13: 2.8m ceiling height, column free floor plate, ~4000 sf gross typical floor plate/Sam Li (7 Jun 2011):Fully leased | AR13: TS034 | AV13: MULTIPOLYGON (((114.174830346 22.2996842730001,114.174847126 22.2996318240001,114.174942245 22.2996585990001,114.175003454 22.299467296,114.174852672 22.2994253020001,114.174770018 22.2996871050001,114.174824529 22.29970245,114.174830346 22.2996842730001)))
A14: 寧晉中心 | B14: Legend Tower | C14: 7 Shing Yip Street | E14: Kwun Tong | F14: =VLOOKUP(Table1[[#This Row],[CBRE sub-markets]],Reference!$A$2:$B$31,2,FALSE) -> Kowloon East | G14: =VLOOKUP(Table1[[#This Row],[CBRE sub-markets]],Reference!$A$2:$D$31,3,FALSE) -> 7 | H14: =VLOOKUP(Table1[[#This Row],[CBRE sub-markets]],Reference!$A$2:$D$31,4,FALSE) -> Kowloon | I14: 2010 | J14: 1 | K14: =IF(ISNUMBER(Table1[[#This Row],[Qtr]]),CONCATENATE(Table1[[#This Row],[Year]]," Q",Table1[[#This Row],[Qtr]]),CONCATENATE(Table1[[#This Row],[Year]],Table1[[#This Row],[Qtr]])) -> 2010 Q1 | L14: A Office | M14: Completed | N14: 1 | O14: 32 | Q14: 18500 | R14: =Q14*(Y14/W14) -> 13875 | S14: =IF(AND(ISNUMBER(R14),R14>=15000),"Yes",IF(R14="","Unknown","No")) -> No | V14: =Table1[[#This Row],[Office GFA (sf)]]/10.7639 -> 36109.031 | W14: 388674 | X14: =Table1[[#This Row],[Office UFA (Net) (sf)]]/10.7639 -> 27081.773 | Y14: 291505.5 | AC14: =IF(Table1[[#This Row],[For Sale or For Lease?]]="For Lease",Table1[[#This Row],[Office UFA (Net) (sf)]]-Table1[[#This Row],[Pre-leased space (Usable FA) (sf)]]-Table1[[#This Row],[Pre-sold (Usable FA) (sf)]]-Table1[[#This Row],[Self-use space (Usable FA) (sf)]],0) -> 0 | AD14: =IF(Table1[[#This Row],[For Sale or For Lease?]]="For Sale",Table1[[#This Row],[Office UFA (Net) (sf)]]-Table1[[#This Row],[Pre-leased space (Usable FA) (sf)]]-Table1[[#This Row],[Pre-sold (Usable FA) (sf)]]-Table1[[#This Row],[Self-use space (Usable FA) (sf)]],0) -> 291505.5 | AE14: =IF(Table1[[#This Row],[For Sale or For Lease?]]="Uncertain",Table1[[#This Row],[Office UFA (Net) (sf)]]-Table1[[#This Row],[Pre-leased space (Usable FA) (sf)]]-Table1[[#This Row],[Pre-sold (Usable FA) (sf)]]-Table1[[#This Row],[Self-use space (Usable FA) (sf)]],0) -> 0 | AF14: =1-SUM(Table1[[#This Row],[Space available for lease (Usable FA) (sf)]:[Space available uncertain of use (Usable FA) (sf)]])/Table1[[#This Row],[Office UFA (Net) (sf)]] -> 0 | AG14: Commercial | AH14: OP Issued | AI14: BD Monthly Digest | AJ14: 40179 | AK14: 40246 | AM14: Billion Development | AN14: Private Sector | AO14: For Sale | AP14: Strata-title | AR14: KK025
A15: 環球貿易廣場3期 | B15: International Commerce Centre Phase 3 | C15: 1 Austin Road West (Union Square Phase 7) | D15: KIL 11080 | E15: Tsim Sha Tsui West | F15: =VLOOKUP(Table1[[#This Row],[CBRE sub-markets]],Reference!$A$2:$B$31,2,FALSE) -> Tsim Sha Tsui West | G15: =VLOOKUP(Table1[[#This Row],[CBRE sub-markets]],Reference!$A$2:$D$31,3,FALSE) -> 6 | H15: =VLOOKUP(Table1[[#This Row],[CBRE sub-markets]],Reference!$A$2:$D$31,4,FALSE) -> Kowloon | I15: 2010 | J15: 2 | K15: =IF(ISNUMBER(Table1[[#This Row],[Qtr]]),CONCATENATE(Table1[[#This Row],[Year]]," Q",Table1[[#This Row],[Qtr]]),CONCATENATE(Table1[[#This Row],[Year]],Table1[[#This Row],[Qtr]])) -> 2010 Q2 | L15: A Office | M15: Completed | N15: 1 | O15: 108+4basement (78-99/F Total 18 floors) | Q15: 33000 | R15: =Q15*(Y15/W15) -> 25740 | S15: =IF(AND(ISNUMBER(R15),R15>=15000),"Yes",IF(R15="","Unknown","No")) -> Yes | V15: =W15/10.764 -> 55394.649 | W15: =2290606-778371-915967 -> 596268 | X15: =Y15/10.764 -> 43207.826 | Y15: =W15*0.78 -> 465089.04 | AC15: =IF(Table1[[#This Row],[For Sale or For Lease?]]="For Lease",Table1[[#This Row],[Office UFA (Net) (sf)]]-Table1[[#This Row],[Pre-leased space (Usable FA) (sf)]]-Table1[[#This Row],[Pre-sold (Usable FA) (sf)]]-Table1[[#This Row],[Self-use space (Usable FA) (sf)]],0) -> 465089.04 | AD15: =IF(Table1[[#This Row],[For Sale or For Lease?]]="For Sale",Table1[[#This Row],[Office UFA (Net) (sf)]]-Table1[[#This Row],[Pre-leased space (Usable FA) (sf)]]-Table1[[#This Row],[Pre-sold (Usable FA) (sf)]]-Table1[[#This Row],[Self-use space (Usable FA) (sf)]],0) -> 0 | AE15: =IF(Table1[[#This Row],[For Sale or For Lease?]]="Uncertain",Table1[[#This Row],[Office UFA (Net) (sf)]]-Table1[[#This Row],[Pre-leased space (Usable FA) (sf)]]-Table1[[#This Row],[Pre-sold (Usable FA) (sf)]]-Table1[[#This Row],[Self-use space (Usable FA) (sf)]],0) -> 0 | AF15: =1-SUM(Table1[[#This Row],[Space available for lease (Usable FA) (sf)]:[Space available uncertain of use (Usable FA) (sf)]])/Table1[[#This Row],[Office UFA (Net) (sf)]] -> 0 | AG15: Commercial/ Hotel | AH15: OP Issued | AI15: Stacking Plan from OS-Kln | AJ15: 40305 | AK15: 40045 | AL15: Site | AM15: Sun Hung Kai Properties | AN15: Private Sector | AO15: For Lease | AP15: Single owner | AQ15: OS-Kln SamLi (24Mar10): "It is highly likely that verbal confirmation of full OP of the building will be obtained by tomorrow (25 March) and formal OP certificate will be followed in a week time." BD Mar 2010 Mthly Digest: GFA (incl Hotel) = 2,923,189 sf; UFA (incl Hotel) = 1,872,565 sf | AR15: TS031
A16: 嘉里中心 | B16: Kerry Centre | C16: 683 King's Road | E16: Quarry Bay | F16: =VLOOKUP(Table1[[#This Row],[CBRE sub-markets]],Reference!$A$2:$B$31,2,FALSE) -> Hong Kong East | G16: =VLOOKUP(Table1[[#This Row],[CBRE sub-markets]],Reference!$A$2:$D$31,3,FALSE) -> 4 | H16: =VLOOKUP(Table1[[#This Row],[CBRE sub-markets]],Reference!$A$2:$D$31,4,FALSE) -> Hong Kong Island | I16: 2010 | J16: 3 | K16: =IF(ISNUMBER(Table1[[#This Row],[Qtr]]),CONCATENATE(Table1[[#This Row],[Year]]," Q",Table1[[#This Row],[Qtr]]),CONCATENATE(Table1[[#This Row],[Year]],Table1[[#This Row],[Qtr]])) -> 2010 Q3 | L16: A Office | M16: Completed | N16: 1 | O16: 29+4 basement | Q16: =W16/29 -> 14564.655 | R16: =Q16*(Y16/W16) -> 12962.543 | S16: =IF(AND(ISNUMBER(R16),R16>=15000),"Yes",IF(R16="","Unknown","No")) -> No | V16: =Table1[[#This Row],[Office GFA (sf)]]/10.7639 -> 39239.959 | W16: 422375 | X16: =Table1[[#This Row],[Office UFA (Net) (sf)]]/10.7639 -> 34923.564 | Y16: 375913.75 | AC16: =IF(Table1[[#This Row],[For Sale or For Lease?]]="For Lease",Table1[[#This Row],[Office UFA (Net) (sf)]]-Table1[[#This Row],[Pre-leased space (Usable FA) (sf)]]-Table1[[#This Row],[Pre-sold (Usable FA) (sf)]]-Table1[[#This Row],[Self-use space (Usable FA) (sf)]],0) -> 375913.75 | AD16: =IF(Table1[[#This Row],[For Sale or For Lease?]]="For Sale",Table1[[#This Row],[Office UFA (Net) (sf)]]-Table1[[#This Row],[Pre-leased space (Usable FA) (sf)]]-Table1[[#This Row],[Pre-sold (Usable FA) (sf)]]-Table1[[#This Row],[Self-use space (Usable FA) (sf)]],0) -> 0 | AE16: =IF(Table1[[#This Row],[For Sale or For Lease?]]="Uncertain",Table1[[#This Row],[Office UFA (Net) (sf)]]-Table1[[#This Row],[Pre-leased space (Usable FA) (sf)]]-Table1[[#This Row],[Pre-sold (Usable FA) (sf)]]-Table1[[#This Row],[Self-use space (Usable FA) (sf)]],0) -> 0 | AF16: =1-SUM(Table1[[#This Row],[Space available for lease (Usable FA) (sf)]:[Space available uncertain of use (Usable FA) (sf)]])/Table1[[#This Row],[Office UFA (Net) (sf)]] -> 0 | AG16: Commercial | AH16: OP Issued | AI16: BD Monthly Digest | AJ16: 40422 | AK16: 40534 | AM16: Kerry Properties | AN16: Private Sector | AO16: For Lease | AP16: Single owner | AQ16: Completed. AR2008 (Cynthia): Kerry Properties owns 40% of the project; Office + Retail/ Rhodri: Kerry will reserve half of the building for their own use OS-HKI, KT (23Mar10): "the OP is supposed to be completed earlier in Aug 2010 rather than Oct 2010. Expected effective rental for one whole floor is HK$30+." | AR16: HE014
A17: 卓匯中心 | B17: Excel Centre | C17: 483A Castle Peak Road | E17: Cheung Sha Wan | F17: =VLOOKUP(Table1[[#This Row],[CBRE sub-markets]],Reference!$A$2:$B$31,2,FALSE) -> Kowloon Others | G17: =VLOOKUP(Table1[[#This Row],[CBRE sub-markets]],Reference!$A$2:$D$31,3,FALSE) -> 8 | H17: =VLOOKUP(Table1[[#This Row],[CBRE sub-markets]],Reference!$A$2:$D$31,4,FALSE) -> Kowloon | I17: 2010 | J17: 4 | K17: =IF(ISNUMBER(Table1[[#This Row],[Qtr]]),CONCATENATE(Table1[[#This Row],[Year]]," Q",Table1[[#This Row],[Qtr]]),CONCATENATE(Table1[[#This Row],[Year]],Table1[[#This Row],[Qtr]])) -> 2010 Q4 | L17: B Office | M17: Completed | N17: 1 | O17: 32 | Q17: 5961 | R17: =Q17*(Y17/W17) -> 4253.4982 | S17: =IF(AND(ISNUMBER(R17),R17>=15000),"Yes",IF(R17="","Unknown","No")) -> No | V17: 9768 | W17: =+V17*10.764 -> 105142.75 | X17: 6970 | Y17: =+X17*10.764 -> 75025.08 | AC17: =IF(Table1[[#This Row],[For Sale or For Lease?]]="For Lease",Table1[[#This Row],[Office UFA (Net) (sf)]]-Table1[[#This Row],[Pre-leased space (Usable FA) (sf)]]-Table1[[#This Row],[Pre-sold (Usable FA) (sf)]]-Table1[[#This Row],[Self-use space (Usable FA) (sf)]],0) -> 75025.08 | AD17: =IF(Table1[[#This Row],[For Sale or For Lease?]]="For Sale",Table1[[#This Row],[Office UFA (Net) (sf)]]-Table1[[#This Row],[Pre-leased space (Usable FA) (sf)]]-Table1[[#This Row],[Pre-sold (Usable FA) (sf)]]-Table1[[#This Row],[Self-use space (Usable FA) (sf)]],0) -> 0 | AE17: =IF(Table1[[#This Row],[For Sale or For Lease?]]="Uncertain",Table1[[#This Row],[Office UFA (Net) (sf)]]-Table1[[#This Row],[Pre-leased space (Usable FA) (sf)]]-Table1[[#This Row],[Pre-sold (Usable FA) (sf)]]-Table1[[#This Row],[Self-use space (Usable FA) (sf)]],0) -> 0 | AF17: =1-SUM(Table1[[#This Row],[Space available for lease (Usable FA) (sf)]:[Space available uncertain of use (Usable FA) (sf)]])/Table1[[#This Row],[Office UFA (Net) (sf)]] -> 0 | AG17: Commercial | AH17: OP Issued | AI17: BD Monthly Digest | AJ17: 40513 | AK17: 40682 | AL17: Redevelopment | AM17: Sun Hung Kai Properties | AN17: Private Sector | AO17: For Lease | AP17: Single owner | AQ17: OP received Dec 2010 | AR17: NS016 | AV17: MULTIPOLYGON (((114.150213458 22.3388642,114.150290204 22.338671905,114.150094899 22.338604542,114.149998219 22.338847463,114.150031777 22.338858595,114.150050887 22.3388076410001,114.150213458 22.3388642)))
B18: 50 Connaught Road Central | C18: 50 Connaught Road Central | E18: Central | F18: =VLOOKUP(Table1[[#This Row],[CBRE sub-markets]],Reference!$A$2:$B$31,2,FALSE) -> Central | G18: =VLOOKUP(Table1[[#This Row],[CBRE sub-markets]],Reference!$A$2:$D$31,3,FALSE) -> 1 | H18: =VLOOKUP(Table1[[#This Row],[CBRE sub-markets]],Reference!$A$2:$D$31,4,FALSE) -> Hong Kong Island | I18: 2011 | J18: 1 | K18: =IF(ISNUMBER(Table1[[#This Row],[Qtr]]),CONCATENATE(Table1[[#This Row],[Year]]," Q",Table1[[#This Row],[Qtr]]),CONCATENATE(Table1[[#This Row],[Year]],Table1[[#This Row],[Qtr]])) -> 2011 Q1 | L18: A Office | M18: Completed | N18: 1 | O18: 28 | Q18: =W18/O18 -> 5277.4643 | R18: =Q18*(Y18/W18) -> 4380.2954 | S18: =IF(AND(ISNUMBER(R18),R18>=15000),"Yes",IF(R18="","Unknown","No")) -> No | V18: =Table1[[#This Row],[Office GFA (sf)]]/10.7639 -> 13728.203 | W18: 147769 | X18: =Table1[[#This Row],[Office UFA (Net) (sf)]]/10.7639 -> 11394.408 | Y18: 122648.27 | AC18: =IF(Table1[[#This Row],[For Sale or For Lease?]]="For Lease",Table1[[#This Row],[Office UFA (Net) (sf)]]-Table1[[#This Row],[Pre-leased space (Usable FA) (sf)]]-Table1[[#This Row],[Pre-sold (Usable FA) (sf)]]-Table1[[#This Row],[Self-use space (Usable FA) (sf)]],0) -> 122648.27 | AD18: =IF(Table1[[#This Row],[For Sale or For Lease?]]="For Sale",Table1[[#This Row],[Office UFA (Net) (sf)]]-Table1[[#This Row],[Pre-leased space (Usable FA) (sf)]]-Table1[[#This Row],[Pre-sold (Usable FA) (sf)]]-Table1[[#This Row],[Self-use space (Usable FA) (sf)]],0) -> 0 | AE18: =IF(Table1[[#This Row],[For Sale or For Lease?]]="Uncertain",Table1[[#This Row],[Office UFA (Net) (sf)]]-Table1[[#This Row],[Pre-leased space (Usable FA) (sf)]]-Table1[[#This Row],[Pre-sold (Usable FA) (sf)]]-Table1[[#This Row],[Self-use space (Usable FA) (sf)]],0) -> 0 | AF18: =1-SUM(Table1[[#This Row],[Space available for lease (Usable FA) (sf)]:[Space available uncertain of use (Usable FA) (sf)]])/Table1[[#This Row],[Office UFA (Net) (sf)]] -> 0 | AG18: Commercial | AH18: OP Issued | AI18: BD Monthly Digest | AJ18: 40575 | AK18: 40675 | AL18: Redevelopment | AM18: Century Land Ltd (Citi Group/Apollo) / National Properties | AN18: Private Sector | AO18: For Lease | AP18: Single owner | AQ18: May 2012: sold to Agricultural Bank of China for $4.88 billion. Deal done by Colliers. | AR18: CC037
B19: One Island South | C19: 2 Heung Yip Road | E19: Wong Chuk Hang | F19: =VLOOKUP(Table1[[#This Row],[CBRE sub-markets]],Reference!$A$2:$B$31,2,FALSE) -> Wong Chuk Hang | G19: =VLOOKUP(Table1[[#This Row],[CBRE sub-markets]],Reference!$A$2:$D$31,3,FALSE) -> 5 | H19: =VLOOKUP(Table1[[#This Row],[CBRE sub-markets]],Reference!$A$2:$D$31,4,FALSE) -> Hong Kong Island | I19: 2011 | J19: 1 | K19: =IF(ISNUMBER(Table1[[#This Row],[Qtr]]),CONCATENATE(Table1[[#This Row],[Year]]," Q",Table1[[#This Row],[Qtr]]),CONCATENATE(Table1[[#This Row],[Year]],Table1[[#This Row],[Qtr]])) -> 2011 Q1 | L19: A Office | M19: Completed | N19: 1 | O19: 31 | Q19: =W19/O19 -> 20200.355 | R19: =Q19*(Y19/W19) -> 15856.037 | S19: =IF(AND(ISNUMBER(R19),R19>=15000),"Yes",IF(R19="","Unknown","No")) -> Yes | V19: =Table1[[#This Row],[Office GFA (sf)]]/10.7639 -> 58176.962 | W19: 626211 | X19: =Table1[[#This Row],[Office UFA (Net) (sf)]]/10.7639 -> 45665.34 | Y19: 491537.15 | AC19: =IF(Table1[[#This Row],[For Sale or For Lease?]]="For Lease",Table1[[#This Row],[Office UFA (Net) (sf)]]-Table1[[#This Row],[Pre-leased space (Usable FA) (sf)]]-Table1[[#This Row],[Pre-sold (Usable FA) (sf)]]-Table1[[#This Row],[Self-use space (Usable FA) (sf)]],0) -> 0 | AD19: =IF(Table1[[#This Row],[For Sale or For Lease?]]="For Sale",Table1[[#This Row],[Office UFA (Net) (sf)]]-Table1[[#This Row],[Pre-leased space (Usable FA) (sf)]]-Table1[[#This Row],[Pre-sold (Usable FA) (sf)]]-Table1[[#This Row],[Self-use space (Usable FA) (sf)]],0) -> 491537.15 | AE19: =IF(Table1[[#This Row],[For Sale or For Lease?]]="Uncertain",Table1[[#This Row],[Office UFA (Net) (sf)]]-Table1[[#This Row],[Pre-leased space (Usable FA) (sf)]]-Table1[[#This Row],[Pre-sold (Usable FA) (sf)]]-Table1[[#This Row],[Self-use space (Usable FA) (sf)]],0) -> 0 | AF19: =1-SUM(Table1[[#This Row],[Space available for lease (Usable FA) (sf)]:[Space available uncertain of use (Usable FA) (sf)]])/Table1[[#This Row],[Office UFA (Net) (sf)]] -> 0 | AG19: Commercial | AH19: OP Issued | AI19: BD Monthly Digest | AJ19: 40575 | AK19: 40675 | AL19: Redevelopment | AM19: Wheelock Properties | AN19: Private Sector | AO19: For Sale | AP19: Strata-title | AQ19: Aug 2011 (Cynthia): Completed. Building both for sale and lease by landlord. | AR19: WCH003
B20: 18 Kowloon East (Po Lung Centre redevelopment) | C20: 18 Wang Chiu Road | E20: Kowloon Bay | F20: =VLOOKUP(Table1[[#This Row],[CBRE sub-markets]],Reference!$A$2:$B$31,2,FALSE) -> Kowloon East | G20: =VLOOKUP(Table1[[#This Row],[CBRE sub-markets]],Reference!$A$2:$D$31,3,FALSE) -> 7 | H20: =VLOOKUP(Table1[[#This Row],[CBRE sub-markets]],Reference!$A$2:$D$31,4,FALSE) -> Kowloon | I20: 2011 | J20: 1 | K20: =IF(ISNUMBER(Table1[[#This Row],[Qtr]]),CONCATENATE(Table1[[#This Row],[Year]]," Q",Table1[[#This Row],[Qtr]]),CONCATENATE(Table1[[#This Row],[Year]],Table1[[#This Row],[Qtr]])) -> 2011 Q1 | L20: A Office | M20: Completed | N20: 1 | O20: 27 | Q20: 22000 | R20: =Q20*(Y20/W20) -> 16720 | S20: =IF(AND(ISNUMBER(R20),R20>=15000),"Yes",IF(R20="","Unknown","No")) -> Yes | V20: =Table1[[#This Row],[Office GFA (sf)]]/10.7639 -> 38461.896 | W20: 414000 | X20: =Table1[[#This Row],[Office UFA (Net) (sf)]]/10.7639 -> 29231.041 | Y20: 314640 | AC20: =IF(Table1[[#This Row],[For Sale or For Lease?]]="For Lease",Table1[[#This Row],[Office UFA (Net) (sf)]]-Table1[[#This Row],[Pre-leased space (Usable FA) (sf)]]-Table1[[#This Row],[Pre-sold (Usable FA) (sf)]]-Table1[[#This Row],[Self-use space (Usable FA) (sf)]],0) -> 314640 | AD20: =IF(Table1[[#This Row],[For Sale or For Lease?]]="For Sale",Table1[[#This Row],[Office UFA (Net) (sf)]]-Table1[[#This Row],[Pre-leased space (Usable FA) (sf)]]-Table1[[#This Row],[Pre-sold (Usable FA) (sf)]]-Table1[[#This Row],[Self-use space (Usable FA) (sf)]],0) -> 0 | AE20: =IF(Table1[[#This Row],[For Sale or For Lease?]]="Uncertain",Table1[[#This Row],[Office UFA (Net) (sf)]]-Table1[[#This Row],[Pre-leased space (Usable FA) (sf)]]-Table1[[#This Row],[Pre-sold (Usable FA) (sf)]]-Table1[[#This Row],[Self-use space (Usable FA) (sf)]],0) -> 0 | AF20: =1-SUM(Table1[[#This Row],[Space available for lease (Usable FA) (sf)]:[Space available uncertain of use (Usable FA) (sf)]])/Table1[[#This Row],[Office UFA (Net) (sf)]] -> 0 | AG20: Commercial | AH20: OP Issued | AI20: BD Monthly Digest | AJ20: 40544 | AK20: 40675 | AL20: Redevelopment | AM20: Sino Land | AN20: Private Sector | AO20: For Lease | AP20: Single owner | AQ20: 03Nov2010 (SamLi): Low zone for lease – landlord expects HK$21 effective, benchmarking ET recent transactions (HK$21 for a 5k sfg unit); High zone for sale – looking for over HK$6k psf. Will be handled by different team from Sino Land/ With retail area, sky garden on 9/Fr Raised floor system, in-house caparking spaces. | AR20: CC040
A21: 萬兆豐中心 | B21: MG Tower | C21: 133 Hoi Bun Road | E21: Kwun Tong | F21: =VLOOKUP(Table1[[#This Row],[CBRE sub-markets]],Reference!$A$2:$B$31,2,FALSE) -> Kowloon East | G21: =VLOOKUP(Table1[[#This Row],[CBRE sub-markets]],Reference!$A$2:$D$31,3,FALSE) -> 7 | H21: =VLOOKUP(Table1[[#This Row],[CBRE sub-markets]],Reference!$A$2:$D$31,4,FALSE) -> Kowloon | I21: 2011 | J21: 2 | K21: =IF(ISNUMBER(Table1[[#This Row],[Qtr]]),CONCATENATE(Table1[[#This Row],[Year]]," Q",Table1[[#This Row],[Qtr]]),CONCATENATE(Table1[[#This Row],[Year]],Table1[[#This Row],[Qtr]])) -> 2011 Q2 | L21: A Office | M21: Completed | N21: 1 | O21: 25 | Q21: =+W21/O21 -> 24519.4 | R21: =Q21*(Y21/W21) -> 17891.16 | S21: =IF(AND(ISNUMBER(R21),R21>=15000),"Yes",IF(R21="","Unknown","No")) -> Yes | V21: =Table1[[#This Row],[Office GFA (sf)]]/10.7639 -> 56948.225 | W21: 612985 | X21: =Table1[[#This Row],[Office UFA (Net) (sf)]]/10.7639 -> 41553.619 | Y21: 447279 | AC21: =IF(Table1[[#This Row],[For Sale or For Lease?]]="For Lease",Table1[[#This Row],[Office UFA (Net) (sf)]]-Table1[[#This Row],[Pre-leased space (Usable FA) (sf)]]-Table1[[#This Row],[Pre-sold (Usable FA) (sf)]]-Table1[[#This Row],[Self-use space (Usable FA) (sf)]],0) -> 0 | AD21: =IF(Table1[[#This Row],[For Sale or For Lease?]]="For Sale",Table1[[#This Row],[Office UFA (Net) (sf)]]-Table1[[#This Row],[Pre-leased space (Usable FA) (sf)]]-Table1[[#This Row],[Pre-sold (Usable FA) (sf)]]-Table1[[#This Row],[Self-use space (Usable FA) (sf)]],0) -> 447279 | AE21: =IF(Table1[[#This Row],[For Sale or For Lease?]]="Uncertain",Table1[[#This Row],[Office UFA (Net) (sf)]]-Table1[[#This Row],[Pre-leased space (Usable FA) (sf)]]-Table1[[#This Row],[Pre-sold (Usable FA) (sf)]]-Table1[[#This Row],[Self-use space (Usable FA) (sf)]],0) -> 0 | AF21: =1-SUM(Table1[[#This Row],[Space available for lease (Usable FA) (sf)]:[Space available uncertain of use (Usable FA) (sf)]])/Table1[[#This Row],[Office UFA (Net) (sf)]] -> 0 | AG21: Commercial | AH21: OP Issued | AI21: BD Monthly Digest | AJ21: 40664 | AK21: 40764 | AL21: Redevelopment | AM21: Billion Development | AN21: Private Sector | AO21: For Sale | AP21: Strata-title | AR21: KK035
B22: 16 Hart Avenue | C22: 16 Hart Avenue | E22: Tsim Sha Tsui | F22: =VLOOKUP(Table1[[#This Row],[CBRE sub-markets]],Reference!$A$2:$B$31,2,FALSE) -> Tsim Sha Tsui | G22: =VLOOKUP(Table1[[#This Row],[CBRE sub-markets]],Reference!$A$2:$D$31,3,FALSE) -> 6 | H22: =VLOOKUP(Table1[[#This Row],[CBRE sub-markets]],Reference!$A$2:$D$31,4,FALSE) -> Kowloon | I22: 2011 | J22: 3 | K22: =IF(ISNUMBER(Table1[[#This Row],[Qtr]]),CONCATENATE(Table1[[#This Row],[Year]]," Q",Table1[[#This Row],[Qtr]]),CONCATENATE(Table1[[#This Row],[Year]],Table1[[#This Row],[Qtr]])) -> 2011 Q3 | L22: B Office | M22: Completed | N22: 1 | O22: 23 | Q22: =W22/O22 -> 1035.6372 | R22: =Q22*0.75 -> 776.7279 | S22: =IF(AND(ISNUMBER(R22),R22>=15000),"Yes",IF(R22="","Unknown","No")) -> No | V22: 2212.9 | W22: =+V22*10.764 -> 23819.656 | X22: =Y22/10.764 -> 1659.675 | Y22: =W22*0.75 -> 17864.742 | AC22: =IF(Table1[[#This Row],[For Sale or For Lease?]]="For Lease",Table1[[#This Row],[Office UFA (Net) (sf)]]-Table1[[#This Row],[Pre-leased space (Usable FA) (sf)]]-Table1[[#This Row],[Pre-sold (Usable FA) (sf)]]-Table1[[#This Row],[Self-use space (Usable FA) (sf)]],0) -> 17864.742 | AD22: =IF(Table1[[#This Row],[For Sale or For Lease?]]="For Sale",Table1[[#This Row],[Office UFA (Net) (sf)]]-Table1[[#This Row],[Pre-leased space (Usable FA) (sf)]]-Table1[[#This Row],[Pre-sold (Usable FA) (sf)]]-Table1[[#This Row],[Self-use space (Usable FA) (sf)]],0) -> 0 | AE22: =IF(Table1[[#This Row],[For Sale or For Lease?]]="Uncertain",Table1[[#This Row],[Office UFA (Net) (sf)]]-Table1[[#This Row],[Pre-leased space (Usable FA) (sf)]]-Table1[[#This Row],[Pre-sold (Usable FA) (sf)]]-Table1[[#This Row],[Self-use space (Usable FA) (sf)]],0) -> 0 | AF22: =1-SUM(Table1[[#This Row],[Space available for lease (Usable FA) (sf)]:[Space available uncertain of use (Usable FA) (sf)]])/Table1[[#This Row],[Office UFA (Net) (sf)]] -> 0 | AG22: Commercial | AH22: Plans Approved | AI22: BD Monthly Digest | AJ22: 40057 | AK22: 40122 | AM22: Cheong Ming Investment Co Ltd | AN22: Private Sector | AO22: For Lease | AP22: Single owner | AQ22: Sep 2011: OS to check whether it's office, retail, or serviced apartment near the Masterpiece | AR22: NS021 | AV22: MULTIPOLYGON (((114.175063536 22.2982295270001,114.175053883 22.2983822330001,114.175115847 22.2983857720001,114.175126259 22.2982331290001,114.175063536 22.2982295270001)))
A23: 陸海通大廈 | B23: LHT Tower | C23: 31 Queen's Road Central & 1-7 Theatre Lane | E23: Central | F23: =VLOOKUP(Table1[[#This Row],[CBRE sub-markets]],Reference!$A$2:$B$31,2,FALSE) -> Central | G23: =VLOOKUP(Table1[[#This Row],[CBRE sub-markets]],Reference!$A$2:$D$31,3,FALSE) -> 1 | H23: =VLOOKUP(Table1[[#This Row],[CBRE sub-markets]],Reference!$A$2:$D$31,4,FALSE) -> Hong Kong Island | I23: 2011 | J23: 4 | K23: =IF(ISNUMBER(Table1[[#This Row],[Qtr]]),CONCATENATE(Table1[[#This Row],[Year]]," Q",Table1[[#This Row],[Qtr]]),CONCATENATE(Table1[[#This Row],[Year]],Table1[[#This Row],[Qtr]])) -> 2011 Q4 | L23: A Office | M23: Completed | N23: 1 | O23: 28+1 basement | Q23: =W23/28 -> 4170.75 | R23: =Q23*(Y23/W23) -> 3781.8214 | S23: =IF(AND(ISNUMBER(R23),R23>=15000),"Yes",IF(R23="","Unknown","No")) -> No | V23: =Table1[[#This Row],[Office GFA (sf)]]/10.7639 -> 10849.32 | W23: 116781 | X23: =Table1[[#This Row],[Office UFA (Net) (sf)]]/10.7639 -> 9837.6053 | Y23: 105891 | AC23: =IF(Table1[[#This Row],[For Sale or For Lease?]]="For Lease",Table1[[#This Row],[Office UFA (Net) (sf)]]-Table1[[#This Row],[Pre-leased space (Usable FA) (sf)]]-Table1[[#This Row],[Pre-sold (Usable FA) (sf)]]-Table1[[#This Row],[Self-use space (Usable FA) (sf)]],0) -> 105891 | AD23: =IF(Table1[[#This Row],[For Sale or For Lease?]]="For Sale",Table1[[#This Row],[Office UFA (Net) (sf)]]-Table1[[#This Row],[Pre-leased space (Usable FA) (sf)]]-Table1[[#This Row],[Pre-sold (Usable FA) (sf)]]-Table1[[#This Row],[Self-use space (Usable FA) (sf)]],0) -> 0 | AE23: =IF(Table1[[#This Row],[For Sale or For Lease?]]="Uncertain",Table1[[#This Row],[Office UFA (Net) (sf)]]-Table1[[#This Row],[Pre-leased space (Usable FA) (sf)]]-Table1[[#This Row],[Pre-sold (Usable FA) (sf)]]-Table1[[#This Row],[Self-use space (Usable FA) (sf)]],0) -> 0 | AF23: =1-SUM(Table1[[#This Row],[Space available for lease (Usable FA) (sf)]:[Space available uncertain of use (Usable FA) (sf)]])/Table1[[#This Row],[Office UFA (Net) (sf)]] -> 0 | AG23: Commercial | AH23: OP Issued | AI23: BD Monthly Digest | AJ23: 40878 | AK23: 40941 | AL23: Redevelopment | AM23: The Luk Hoi Tong Corporation Ltd | AN23: Private Sector | AO23: For Lease | AP23: Single owner | AR23: CC038
